<?xml version="1.0" ?>
<sdf version="1.7">
<model name="gripper_model">
  <link name="base">
    <pose>-0.045 0.0 0.015 0 0 0</pose>
    <inertial>
      <inertia>
        <ixx>3.0466176e-05</ixx>
        <ixy>0</ixy>
        <ixz>0</ixz>
        <iyy>3.0466176e-05</iyy>
        <iyz>0</iyz>
        <izz>3.0466176e-05</izz>
      </inertia>
      <mass>0.02</mass>
    </inertial>
    <collision name="collision">
      <pose>0 0 0 0 0 0</pose>
      <geometry>
        <box>
          <size>0.06 0.135 0.03</size>
        </box>
      </geometry>
    </collision>
    <visual name="visual">
      <geometry>
        <box>
          <size>0.06 0.135 0.03</size>
        </box>
      </geometry>
    </visual>
  </link>
  <link name="riser">
    <pose>-0.045 0.0 0.045 0 0 0</pose>
    <inertial>
      <inertia>
        <ixx>3.0466176e-05</ixx>
        <ixy>0</ixy>
        <ixz>0</ixz>
        <iyy>3.0466176e-05</iyy>
        <iyz>0</iyz>
        <izz>3.0466176e-05</izz>
      </inertia>
      <mass>0.02</mass>
    </inertial>
    <collision name="collisiontop">
      <pose>0 0 0.00825 1.57 0 0</pose>
      <geometry>
        <box>
          <size>0.06 0.0135 0.018</size>
        </box>
      </geometry>
    </collision>
    <collision name="collisionbottom">
      <pose>0 0 -0.00825 1.57 0 0</pose>
      <geometry>
        <box>
          <size>0.06 0.0135 0.018</size>
        </box>
      </geometry>
    </collision>
    <collision name="collisionleft">
      <pose>0 0.0195 0 1.57 0 0</pose>
      <geometry>
        <box>
          <size>0.06 0.03 0.021</size>
        </box>
      </geometry>
    </collision>
    <collision name="collisionright">
      <pose>0 -0.0195 0 1.57 0 0</pose>
      <geometry>
        <box>
          <size>0.06 0.03 0.021</size>
        </box>
      </geometry>
    </collision>
    <collision name="collisionmiddle">
      <pose>0 0 0 1.57 0 0</pose>
      <geometry>
        <box>
          <size>0.06 0.003 0.012</size>
        </box>
      </geometry>
    </collision>
    <visual name="visual">
      <geometry>
        <box>
          <size>0.06 0.135 0.03</size>
        </box>
      </geometry>
    </visual>
    <self_collide>1</self_collide>
  </link>
  <link name="palm">
    <pose>0.064 0.0 0.045 0 0 0</pose>
    <inertial>
      <inertia>
        <ixx>3.0466176e-05</ixx>
        <ixy>0</ixy>
        <ixz>0</ixz>
        <iyy>3.0466176e-05</iyy>
        <iyz>0</iyz>
        <izz>3.0466176e-05</izz>
      </inertia>
      <mass>0.015</mass>
    </inertial>
    <collision name="collision">
      <pose>0.010 0 0 0 0 0</pose>
      <geometry>
        <box>
          <size>0.006 0.02 0.025</size>
        </box>
      </geometry>
    </collision>
    <visual name="visual">
      <pose>0.010 0 0 0 0 0</pose>
      <geometry>
        <box>
          <size>0.006 0.02 0.025</size>
        </box>
      </geometry>
    </visual>
    <self_collide>1</self_collide>
    <sensor name='contact_sensor' type='contact'>
      <update_rate>20</update_rate>
      <contact>
        <collision>collision</collision>
      </contact>
      <plugin name="contact_plugin" filename="/opt/ros/noetic/lib/libgazebo_ros_bumper.so">
        <bumperTopicName>contactsensor</bumperTopicName>
        <frameName>world</frameName>
      </plugin>
    </sensor>
  </link>
  <joint name="fix_palm" type="fixed">
    <child>palm</child>
    <parent>riser</parent>
  </joint>
  <link name="left_finger_link">
    <pose relative_to="riser">0.06 0.0375 0 0 0 -0.52359</pose>
    <inertial>
      <inertia>
        <ixx>3.0466176e-05</ixx>
        <ixy>0</ixy>
        <ixz>0</ixz>
        <iyy>3.0466176e-05</iyy>
        <iyz>0</iyz>
        <izz>3.0466176e-05</izz>
      </inertia>
      <mass>0.015</mass>
    </inertial>
    <collision name="collisiontop">
      <pose>0 0 0.00825 0 0 0</pose>
      <geometry>
        <cylinder>
          <radius>0.03</radius>
          <length>0.0135</length>
        </cylinder>
      </geometry>
    </collision>
    <collision name="collisionmiddle">
      <geometry>
        <cylinder>
          <radius>0.027</radius>
          <length>0.003</length>
        </cylinder>
      </geometry>
    </collision>
    <collision name="collisionbottom">
      <pose>0 0 -0.00825 0 0 0</pose>
      <geometry>
        <cylinder>
          <radius>0.03</radius>
          <length>0.0135</length>
        </cylinder>
      </geometry>
    </collision>
    <visual name="visualtop">
      <pose>0 0 0.00825 0 0 0</pose>
      <geometry>
        <cylinder>
          <radius>0.03</radius>
          <length>0.0135</length>
        </cylinder>
      </geometry>
    </visual>
    <visual name="visualmiddle">
      <geometry>
        <cylinder>
          <radius>0.027</radius>
          <length>0.003</length>
        </cylinder>
      </geometry>
    </visual>
    <visual name="visualbottom">
      <pose>0 0 -0.00825 0 0 0</pose>
      <geometry>
        <cylinder>
          <radius>0.03</radius>
          <length>0.0135</length>
        </cylinder>
      </geometry>
    </visual>
    <self_collide>1</self_collide>
  </link>
  <link name="left_finger">
    <pose relative_to="left_finger_link">0.024 0.075 0 0 0 0</pose>
    <inertial>
      <inertia>
        <ixx>3.0466176e-05</ixx>
        <ixy>0</ixy>
        <ixz>0</ixz>
        <iyy>3.0466176e-05</iyy>
        <iyz>0</iyz>
        <izz>3.0466176e-05</izz>
      </inertia>
      <mass>0.015</mass>
    </inertial>
    <collision name="collisionleft">
      <pose>0.01125 0 0 1.57 0 0</pose>
      <geometry>
        <box>
          <size>0.0075 0.03 0.09</size>
        </box>
      </geometry>
    </collision>
    <collision name="collisionright">
      <pose>-0.01125 0 0 1.57 0 0</pose>
      <geometry>
        <box>
          <size>0.0075 0.03 0.09</size>
        </box>
      </geometry>
    </collision>
    <collision name="collisiontop">
      <pose>0 0 0.00825 1.57 0 0</pose>
      <geometry>
        <box>
          <size>0.015 0.0135 0.09</size>
        </box>
      </geometry>
    </collision>
    <collision name="collisionbottom">
      <pose>0 0 -0.00825 1.57 0 0</pose>
      <geometry>
        <box>
          <size>0.015 0.0135 0.09</size>
        </box>
      </geometry>
    </collision>
    <visual name="visual">
      <pose>0 0 0 1.57 0 0</pose>
      <geometry>
        <mesh>
          <scale>0.3 0.3 0.3</scale>
          <uri>model://gripper_model/meshes/gripper_finger.stl</uri>
        </mesh>
      </geometry>
    </visual>
    <self_collide>1</self_collide>
  </link>
  <link name="soft_left_finger_pad">
    <pose relative_to="left_finger">0.018 0 0 1.5708 0 1.5708</pose>
    <inertial>
      <pose>0 0 0 0 0 0</pose>
      <inertia>
        <ixx>3.046617599999999e-06</ixx>
        <ixy>0</ixy>
        <ixz>0</ixz>
        <iyy>3.046617599999999e-06</iyy>
        <iyz>0</iyz>
        <izz>3.046617599999999e-06</izz>
      </inertia>
      <mass>0.003</mass>
    </inertial>
    <collision name="collision">
      <geometry>
        <box>
          <size>0.09 0.03 0.006</size>
        </box>
      </geometry>
      <surface>
        <contact>
          <ode>
            <soft_erp>0.2</soft_erp>
            <kp>1400</kp>
            <kd>0.5</kd>
            <max_vel>0.2</max_vel>
            <min_depth>0.05</min_depth>
          </ode>
        </contact>
        <friction>
          <ode>
            <mu>5.0</mu>
            <mu2>5.0</mu2>
          </ode>
        </friction>
      </surface>
    </collision>
    <visual name="visual">
      <geometry>
        <box>
          <size>0.09 0.03 0.006</size>
        </box>
      </geometry>
      <material>
        <script>
          <name>Gazebo/Gray</name>
          <uri>file://media/materials/scripts/gazebo.material</uri>
        </script>
      </material>
    </visual>
  </link>
  <link name="left_finger_tip_link">
    <pose relative_to="left_finger">-0.009 0.063 0 0 0 -0.645772</pose>
    <inertial>
      <inertia>
        <ixx>3.0466176e-05</ixx>
        <ixy>0</ixy>
        <ixz>0</ixz>
        <iyy>3.0466176e-05</iyy>
        <iyz>0</iyz>
        <izz>3.0466176e-05</izz>
      </inertia>
      <mass>0.015</mass>
    </inertial>
    <collision name="collisiontop">
      <pose>0 0 0.00825 0 0 0</pose>
      <geometry>
        <cylinder>
          <radius>0.018</radius>
          <length>0.0135</length>
        </cylinder>
      </geometry>
    </collision>
    <collision name="collisionmiddle">
      <geometry>
        <cylinder>
          <radius>0.015</radius>
          <length>0.003</length>
        </cylinder>
      </geometry>
    </collision>
    <collision name="collisionbottom">
      <pose>0 0 -0.00825 0 0 0</pose>
      <geometry>
        <cylinder>
          <radius>0.018</radius>
          <length>0.0135</length>
        </cylinder>
      </geometry>
    </collision>
    <visual name="visualtop">
      <pose>0 0 0.00825 0 0 0</pose>
      <geometry>
        <cylinder>
          <radius>0.018</radius>
          <length>0.0135</length>
        </cylinder>
      </geometry>
    </visual>
    <visual name="visualmiddle">
      <geometry>
        <cylinder>
          <radius>0.015</radius>
          <length>0.003</length>
        </cylinder>
      </geometry>
    </visual>
    <visual name="visualbottom">
      <pose>0 0 -0.00825 0 0 0</pose>
      <geometry>
        <cylinder>
          <radius>0.018</radius>
          <length>0.0135</length>
        </cylinder>
      </geometry>
    </visual>
  </link>
  <link name="left_finger_tip_spacer">
    <pose relative_to="left_finger_tip_link">0.0015 0.025500000000000002 0 0 0 0</pose>
    <inertial>
      <inertia>
        <ixx>3.046617599999999e-06</ixx>
        <ixy>0</ixy>
        <ixz>0</ixz>
        <iyy>3.046617599999999e-06</iyy>
        <iyz>0</iyz>
        <izz>3.046617599999999e-06</izz>
      </inertia>
      <mass>0.003</mass>
    </inertial>
    <collision name="collision">
      <geometry>
        <box>
          <size>0.015 0.015 0.03</size>
        </box>
      </geometry>
    </collision>
    <visual name="visual">
      <geometry>
        <box>
          <size>0.015 0.015 0.03</size>
        </box>
      </geometry>
    </visual>
  </link>
  <link name="left_finger_tip">
    <pose relative_to="left_finger_tip_link">0.009 0.063 0 0 0 0</pose>
    <inertial>
      <inertia>
        <ixx>3.0466176e-05</ixx>
        <ixy>0</ixy>
        <ixz>0</ixz>
        <iyy>3.0466176e-05</iyy>
        <iyz>0</iyz>
        <izz>3.0466176e-05</izz>
      </inertia>
      <mass>0.015</mass>
    </inertial>
    <collision name="collision">
      <geometry>
        <box>
          <size>0.03 0.06 0.03</size>
        </box>
      </geometry>
    </collision>
    <visual name="visual">
      <geometry>
        <box>
          <size>0.03 0.06 0.03</size>
        </box>
      </geometry>
    </visual>
    <self_collide>1</self_collide>
  </link>
  <link name="soft_left_fingertip_pad">
    <pose relative_to="left_finger_tip">0.018 0 0 1.5708 0 1.5708</pose>
    <inertial>
      <pose>0 0 0 0 0 0</pose>
      <inertia>
        <ixx>3.046617599999999e-06</ixx>
        <ixy>0</ixy>
        <ixz>0</ixz>
        <iyy>3.046617599999999e-06</iyy>
        <iyz>0</iyz>
        <izz>3.046617599999999e-06</izz>
      </inertia>
      <mass>0.003</mass>
    </inertial>
    <collision name="collision">
      <geometry>
        <box>
          <size>0.06 0.03 0.006</size>
        </box>
      </geometry>
      <surface>
        <contact>
          <ode>
            <soft_cfm>0.5</soft_cfm>
            <soft_erp>0.2</soft_erp>
            <kp>1400</kp>
            <kd>0.5</kd>
            <max_vel>0.2</max_vel>
            <min_depth>0.05</min_depth>
          </ode>
        </contact>
        <friction>
          <ode>
            <mu>5.0</mu>
            <mu2>5.0</mu2>
          </ode>
        </friction>
      </surface>
    </collision>
    <visual name="visual">
      <geometry>
        <box>
          <size>0.06 0.03 0.006</size>
        </box>
      </geometry>
      <material>
        <script>
          <name>Gazebo/Gray</name>
          <uri>file://media/materials/scripts/gazebo.material</uri>
        </script>
      </material>
    </visual>
  </link>
  <link name="right_finger_link">
    <pose relative_to="riser">0.06 -0.0375 0 0 0 0.52359</pose>
    <inertial>
      <inertia>
        <ixx>3.0466176e-05</ixx>
        <ixy>0</ixy>
        <ixz>0</ixz>
        <iyy>3.0466176e-05</iyy>
        <iyz>0</iyz>
        <izz>3.0466176e-05</izz>
      </inertia>
      <mass>0.015</mass>
    </inertial>
    <collision name="collisiontop">
      <pose>0 0 0.00825 0 0 0 </pose>
      <geometry>
        <cylinder>
          <radius>0.03</radius>
          <length>0.0135</length>
        </cylinder>
      </geometry>
    </collision>
    <collision name="collisionmiddle">
      <geometry>
        <cylinder>
          <radius>0.027</radius>
          <length>0.003</length>
        </cylinder>
      </geometry>
    </collision>
    <collision name="collisionbottom">
      <pose>0 0 -0.00825 0 0 0 </pose>
      <geometry>
        <cylinder>
          <radius>0.03</radius>
          <length>0.0135</length>
        </cylinder>
      </geometry>
    </collision>
    <visual name="visualtop">
      <pose>0 0 0.00825 0 0 0 </pose>
      <geometry>
        <cylinder>
          <radius>0.03</radius>
          <length>0.0135</length>
        </cylinder>
      </geometry>
    </visual>
    <visual name="visualmiddle">
      <geometry>
        <cylinder>
          <radius>0.027</radius>
          <length>0.003</length>
        </cylinder>
      </geometry>
    </visual>
    <visual name="visualbottom">
      <pose>0 0 -0.00825 0 0 0 </pose>
      <geometry>
        <cylinder>
          <radius>0.03</radius>
          <length>0.0135</length>
        </cylinder>
      </geometry>
    </visual>
    <self_collide>1</self_collide>
  </link>
  <link name="right_finger">
    <pose relative_to="right_finger_link">0.024 -0.075 0 0 0 0</pose>
    <inertial>
      <inertia>
        <ixx>3.0466176e-05</ixx>
        <ixy>0</ixy>
        <ixz>0</ixz>
        <iyy>3.0466176e-05</iyy>
        <iyz>0</iyz>
        <izz>3.0466176e-05</izz>
      </inertia>
      <mass>0.015</mass>
    </inertial>
    <collision name="collisionleft">
      <pose>0.01125 0 0 1.57 0 0</pose>
      <geometry>
        <box>
          <size>0.0075 0.03 0.09</size>
        </box>
      </geometry>
    </collision>
    <collision name="collisionright">
      <pose>-0.01125 0 0 1.57 0 0</pose>
      <geometry>
        <box>
          <size>0.0075 0.03 0.09</size>
        </box>
      </geometry>
    </collision>
    <collision name="collisiontop">
      <pose>0 0 0.00825 1.57 0 0</pose>
      <geometry>
        <box>
          <size>0.015 0.0135 0.09</size>
        </box>
      </geometry>
    </collision>
    <collision name="collisionbottom">
      <pose>0 0 -0.00825 1.57 0 0</pose>
      <geometry>
        <box>
          <size>0.015 0.0135 0.09</size>
        </box>
      </geometry>
    </collision>
    <visual name="visual">
      <pose>0 0 0 1.57 0 0</pose>
      <geometry>
        <mesh>
          <scale>0.3 0.3 0.3</scale>
          <uri>model://gripper_model/meshes/gripper_finger.stl</uri>
        </mesh>
      </geometry>
    </visual>
    <self_collide>1</self_collide>
  </link>
  <link name="soft_right_finger_pad">
    <pose relative_to="right_finger">0.018 0 0 1.5708 0 1.5708</pose>
    <inertial>
      <pose>0 0 0 0 0 0</pose>
      <inertia>
        <ixx>3.046617599999999e-06</ixx>
        <ixy>0</ixy>
        <ixz>0</ixz>
        <iyy>3.046617599999999e-06</iyy>
        <iyz>0</iyz>
        <izz>3.046617599999999e-06</izz>
      </inertia>
      <mass>0.003</mass>
    </inertial>
    <collision name="collision">
      <geometry>
        <box>
          <size>0.09 0.03 0.006</size>
        </box>
      </geometry>
      <surface>
        <contact>
          <ode>
            <soft_cfm>0.5</soft_cfm>
            <soft_erp>0.2</soft_erp>
            <kp>1400</kp>
            <kd>0.5</kd>
            <max_vel>0.2</max_vel>
            <min_depth>0.05</min_depth>
          </ode>
        </contact>
        <friction>
          <ode>
            <mu>5.0</mu>
            <mu2>5.0</mu2>
          </ode>
        </friction>
      </surface>
    </collision>
    <visual name="visual">
      <geometry>
        <box>
          <size>0.09 0.03 0.006</size>
        </box>
      </geometry>
      <material>
        <script>
          <name>Gazebo/Gray</name>
          <uri>file://media/materials/scripts/gazebo.material</uri>
        </script>
      </material>
    </visual>
  </link>
  <link name="right_finger_tip_link">
    <pose relative_to="right_finger">-0.009 -0.063 0 0 0 0.645772</pose>
    <inertial>
      <inertia>
        <ixx>3.0466176e-05</ixx>
        <ixy>0</ixy>
        <ixz>0</ixz>
        <iyy>3.0466176e-05</iyy>
        <iyz>0</iyz>
        <izz>3.0466176e-05</izz>
      </inertia>
      <mass>0.015</mass>
    </inertial>
    <collision name="collisiontop">
      <pose>0 0 0.00825 0 0 0 </pose>
      <geometry>
        <cylinder>
          <radius>0.018</radius>
          <length>0.0135</length>
        </cylinder>
      </geometry>
    </collision>
    <collision name="collisionmiddle">
      <geometry>
        <cylinder>
          <radius>0.015</radius>
          <length>0.003</length>
        </cylinder>
      </geometry>
    </collision>
    <collision name="collisionbottom">
      <pose>0 0 -0.00825 0 0 0 </pose>
      <geometry>
        <cylinder>
          <radius>0.018</radius>
          <length>0.0135</length>
        </cylinder>
      </geometry>
    </collision>
    <visual name="visualtop">
      <pose>0 0 0.00825 0 0 0 </pose>
      <geometry>
        <cylinder>
          <radius>0.018</radius>
          <length>0.0135</length>
        </cylinder>
      </geometry>
    </visual>
    <visual name="visualmiddle">
      <geometry>
        <cylinder>
          <radius>0.015</radius>
          <length>0.003</length>
        </cylinder>
      </geometry>
    </visual>
    <visual name="visualbottom">
      <pose>0 0 -0.00825 0 0 0 </pose>
      <geometry>
        <cylinder>
          <radius>0.018</radius>
          <length>0.0135</length>
        </cylinder>
      </geometry>
    </visual>
  </link>
  <link name="right_finger_tip_spacer">
    <pose relative_to="right_finger_tip_link">0.0015 -0.025500000000000002 0 0 0 0</pose>
    <inertial>
      <inertia>
        <ixx>3.046617599999999e-06</ixx>
        <ixy>0</ixy>
        <ixz>0</ixz>
        <iyy>3.046617599999999e-06</iyy>
        <iyz>0</iyz>
        <izz>3.046617599999999e-06</izz>
      </inertia>
      <mass>0.003</mass>
    </inertial>
    <collision name="collision">
      <geometry>
        <box>
          <size>0.015 0.015 0.03</size>
        </box>
      </geometry>
    </collision>
    <visual name="visual">
      <geometry>
        <box>
          <size>0.015 0.015 0.03</size>
        </box>
      </geometry>
    </visual>
  </link>
  <link name="right_finger_tip">
    <pose relative_to="right_finger_tip_link">0.009 -0.063 0 0 0 0</pose>
    <inertial>
      <inertia>
        <ixx>3.0466176e-05</ixx>
        <ixy>0</ixy>
        <ixz>0</ixz>
        <iyy>3.0466176e-05</iyy>
        <iyz>0</iyz>
        <izz>3.0466176e-05</izz>
      </inertia>
      <mass>0.015</mass>
    </inertial>
    <collision name="collision">
      <geometry>
        <box>
          <size>0.03 0.06 0.03</size>
        </box>
      </geometry>
    </collision>
    <visual name="visual">
      <geometry>
        <box>
          <size>0.03 0.06 0.03</size>
        </box>
      </geometry>
    </visual>
    <self_collide>1</self_collide>
  </link>
  <link name="soft_right_fingertip_pad">
    <pose relative_to="right_finger_tip">0.018 0 0 1.5708 0 1.5708</pose>
    <inertial>
      <pose>0 0 0 0 0 0</pose>
      <inertia>
        <ixx>3.046617599999999e-06</ixx>
        <ixy>0</ixy>
        <ixz>0</ixz>
        <iyy>3.046617599999999e-06</iyy>
        <iyz>0</iyz>
        <izz>3.046617599999999e-06</izz>
      </inertia>
      <mass>0.003</mass>
    </inertial>
    <collision name="collision">
      <geometry>
        <box>
          <size>0.06 0.03 0.006</size>
        </box>
      </geometry>
      <surface>
        <contact>
          <ode>
            <soft_cfm>0.5</soft_cfm>
            <soft_erp>0.2</soft_erp>
            <kp>1400</kp>
            <kd>0.5</kd>
            <max_vel>0.2</max_vel>
            <min_depth>0.05</min_depth>
          </ode>
        </contact>
        <friction>
          <ode>
            <mu>5.0</mu>
            <mu2>5.0</mu2>
          </ode>
        </friction>
      </surface>
    </collision>
    <visual name="visual">
      <geometry>
        <box>
          <size>0.06 0.03 0.006</size>
        </box>
      </geometry>
      <material>
        <script>
          <name>Gazebo/Gray</name>
          <uri>file://media/materials/scripts/gazebo.material</uri>
        </script>
      </material>
    </visual>
  </link>
  <static>false</static>
  <!-- JOINTS -->
  <joint name="base_riser" type="fixed">
    <child>riser</child>
    <parent>base</parent>
  </joint>
  <joint name="riser_left_finger_link" type="revolute">
    <child>left_finger_link</child>
    <parent>riser</parent>
    <axis>
      <limit>
        <lower>-0.95</lower>
        <upper>0.28</upper>
      </limit>
      <xyz>0 0 1</xyz>
      <dynamics>
        <spring_reference>0</spring_reference>
        <spring_stiffness>0.09</spring_stiffness>
        <damping>0.1</damping>
      </dynamics>
    </axis>
    <sensor name="force_torque1" type="force_torque">
      <update_rate>30</update_rate>
      <force_torque>
        <frame>child</frame>
        <measure_direction>child_to_parent</measure_direction>
      </force_torque>
    </sensor>
  </joint>
  <joint name="fix_left_finger_link" type="fixed">
    <child>left_finger</child>
    <parent>left_finger_link</parent>
  </joint>
  <joint name="joint_left_finger_tip_link" type="revolute">
    <child>left_finger_tip_link</child>
    <parent>left_finger</parent>
    <axis>
      <limit>
        <lower>-0.90</lower>
        <upper>0.17</upper>
      </limit>
      <xyz>0 0 1</xyz>
      <dynamics>
        <spring_reference>0</spring_reference>
        <spring_stiffness>0.09</spring_stiffness>
        <damping>0.1</damping>
      </dynamics>
    </axis>
    <sensor name="force_torque2" type="force_torque">
      <update_rate>30</update_rate>
      <force_torque>
        <frame>child</frame>
        <measure_direction>child_to_parent</measure_direction>
      </force_torque>
    </sensor>
  </joint>
  <joint name="fix_left_finger_tip_link" type="fixed">
    <child>left_finger_tip</child>
    <parent>left_finger_tip_link</parent>
  </joint>
  <joint name="fix_left_finger_tip_spacer" type="fixed">
    <child>left_finger_tip</child>
    <parent>left_finger_tip_spacer</parent>
  </joint>
  <joint name="riser_right_finger_link" type="revolute">
    <child>right_finger_link</child>
    <parent>riser</parent>
    <axis>
      <limit>
        <lower>-0.28</lower>
        <upper>0.95</upper>
      </limit>
      <xyz>0 0 1</xyz>
      <dynamics>
        <spring_reference>0</spring_reference>
        <spring_stiffness>0.09</spring_stiffness>
        <damping>0.1</damping>
      </dynamics>
    </axis>
    <sensor name="force_torque3" type="force_torque">
      <update_rate>30</update_rate>
      <force_torque>
        <frame>child</frame>
        <measure_direction>child_to_parent</measure_direction>
      </force_torque>
    </sensor>
  </joint>
  <joint name="fix_right_finger_link" type="fixed">
    <child>right_finger</child>
    <parent>right_finger_link</parent>
  </joint>
  <joint name="joint_right_finger_tip_link" type="revolute">
    <child>right_finger_tip_link</child>
    <parent>right_finger</parent>
    <axis>
      <limit>
        <lower>-0.17</lower>
        <upper>0.90</upper>
      </limit>
      <xyz>0 0 1</xyz>
      <dynamics>
        <spring_reference>0</spring_reference>
        <spring_stiffness>0.09</spring_stiffness>
        <damping>0.1</damping>
      </dynamics>
    </axis>
    <sensor name="force_torque4" type="force_torque">
      <update_rate>30</update_rate>
      <force_torque>
        <frame>child</frame>
        <measure_direction>child_to_parent</measure_direction>
      </force_torque>
    </sensor>
  </joint>
  <joint name="fix_right_finger_tip_link" type="fixed">
    <child>right_finger_tip</child>
    <parent>right_finger_tip_link</parent>
  </joint>
  <joint name="fix_right_finger_tip_spacer" type="fixed">
    <child>right_finger_tip</child>
    <parent>right_finger_tip_spacer</parent>
  </joint>
  <!-- pad joints -->
  <joint name="soft_left_finger_pad_joint" type="fixed">
    <child>soft_left_finger_pad</child>
    <parent>left_finger</parent>
  </joint>
  <joint name="soft_left_fingertip_pad_joint" type="fixed">
    <child>soft_left_fingertip_pad</child>
    <parent>left_finger_tip</parent>
  </joint>
  <joint name="soft_right_finger_pad_joint" type="fixed">
    <child>soft_right_finger_pad</child>
    <parent>right_finger</parent>
  </joint>
  <joint name="soft_right_fingertip_pad_joint" type="fixed">
    <child>soft_right_fingertip_pad</child>
    <parent>right_finger_tip</parent>
  </joint>
</model>
</sdf>
