<?xml version="1.0" ?>
<sdf version='1.7'>
<model name="pulley">
  <static>false</static>
  <link name="bearing">
    <pose>0 0 0.015 0 0 0</pose>
    <inertial>
      <pose>0 0 0 0 0 0</pose>
      <inertia>
        <ixx>0.00001</ixx>
        <ixy>0</ixy>
        <ixz>0</ixz>
        <iyy>0.00001</iyy>
        <iyz>0</iyz>
        <izz>0.00001</izz>
      </inertia>
      <mass>0.01</mass>
    </inertial>
    <collision name="collisionmiddle">
      <geometry>
        <cylinder>
          <radius>0.012</radius>
          <length>0.003</length>
        </cylinder>
      </geometry>
      <surface>
        <friction>
          <ode>
            <mu>0.001</mu>
            <mu2>0.001</mu2>
          </ode>
        </friction>
      </surface>
    </collision>
    <visual name="visualmiddle">
      <geometry>
        <cylinder>
          <radius>0.012</radius>
          <length>0.003</length>
        </cylinder>
      </geometry>
    </visual>
  </link>
  <link name="top">
    <pose relative_to="bearing">0 0 0.0045 0 0 0</pose>
    <inertial>
      <pose>0 0 0 0 0 0</pose>
      <inertia>
        <ixx>0.00001</ixx>
        <ixy>0</ixy>
        <ixz>0</ixz>
        <iyy>0.00001</iyy>
        <iyz>0</iyz>
        <izz>0.00001</izz>
      </inertia>
      <mass>0.01</mass>
    </inertial>
    <collision name="collisiontop">
      <geometry>
        <cylinder>
          <radius>0.018</radius>
          <length>0.006</length>
        </cylinder>
      </geometry>
    </collision>
    <visual name="visualtop">
      <geometry>
        <cylinder>
          <radius>0.018</radius>
          <length>0.006</length>
        </cylinder>
      </geometry>
    </visual>
  </link>
  <link name="bottom">
    <pose relative_to="bearing">0 0 -0.0045 0 0 0</pose>
    <inertial>
      <pose>0 0 0 0 0 0</pose>
      <inertia>
        <ixx>0.00001</ixx>
        <ixy>0</ixy>
        <ixz>0</ixz>
        <iyy>0.00001</iyy>
        <iyz>0</iyz>
        <izz>0.00001</izz>
      </inertia>
      <mass>0.01</mass>
    </inertial>
    <collision name="collisionbottom">
      <geometry>
        <cylinder>
          <radius>0.018</radius>
          <length>0.006</length>
        </cylinder>
      </geometry>
    </collision>
    <visual name="visualbottom">
      <geometry>
        <cylinder>
          <radius>0.018</radius>
          <length>0.006</length>
        </cylinder>
      </geometry>
    </visual>
  </link>
  <link name="stopper1">
    <pose relative_to="top">0 0.01875 -0.0045 0 0 1.5708</pose>
    <inertial>
      <pose>0 0 0 0 0 0</pose>
      <inertia>
        <ixx>0.00001</ixx>
        <ixy>0</ixy>
        <ixz>0</ixz>
        <iyy>0.00001</iyy>
        <iyz>0</iyz>
        <izz>0.00001</izz>
      </inertia>
      <mass>0.01</mass>
    </inertial>
    <collision name="collision">
      <geometry>
        <box>
          <size>0.0015 0.0075 0.015</size>
        </box>
      </geometry>
    </collision>
    <visual name="visual">
      <geometry>
        <box>
          <size>0.0015 0.0075 0.015</size>
        </box>
      </geometry>
    </visual>
  </link>
  <joint name="stopper1_joint" type="fixed">
    <child>stopper1</child>
    <parent>top</parent>
  </joint>
  <joint name="stopper1a_joint" type="fixed">
    <child>stopper1</child>
    <parent>bottom</parent>
  </joint>
  <link name="stopper2">
    <pose relative_to="top">0 -0.01875 -0.0045 0 0 1.5708</pose>
    <inertial>
      <pose>0 0 0 0 0 0</pose>
      <inertia>
        <ixx>0.00001</ixx>
        <ixy>0</ixy>
        <ixz>0</ixz>
        <iyy>0.00001</iyy>
        <iyz>0</iyz>
        <izz>0.00001</izz>
      </inertia>
      <mass>0.01</mass>
    </inertial>
    <collision name="collision">
      <geometry>
        <box>
          <size>0.0015 0.0075 0.015</size>
        </box>
      </geometry>
    </collision>
    <visual name="visual">
      <geometry>
        <box>
          <size>0.0015 0.0075 0.015</size>
        </box>
      </geometry>
    </visual>
  </link>
  <joint name="stopper2_joint" type="fixed">
    <child>stopper2</child>
    <parent>top</parent>
  </joint>
  <joint name="stopper2a_joint" type="fixed">
    <child>stopper2</child>
    <parent>bottom</parent>
  </joint>
  <!-- JOINTS -->
  <joint name="revolute1" type="revolute">
    <child>bearing</child>
    <parent>top</parent>
    <axis>
      <xyz>0 0 1</xyz>
    </axis>
  </joint>
</model>
</sdf>
